Workbook

Sheet Main Sheet
A3: Invoice No
A4: BK08
A6: Invoice Date | B6: =IFERROR(INDEX(Sheet2!B:B,MATCH('Main Sheet'!A4,Sheet2!A:A,0)),"") -> 45161
A7: Party Name | D7: Trading Company Name
A8: =IFERROR(INDEX(Sheet2!J:J,MATCH('Main Sheet'!A4,Sheet2!A:A,0)),"") -> Kien Coung | D8: =IFERROR(INDEX(Sheet2!K:K,MATCH('Main Sheet'!A4,Sheet2!A:A,0)),"") -> DG Stone
A11: Shipping Bill No. | D11: Shipping Bill Date
A12: =IFERROR(INDEX(Sheet1!C:C,MATCH('Main Sheet'!A4,Sheet1!B:B,0)),"") -> 3440075 | D12: =IFERROR(INDEX(Sheet1!D:D,MATCH('Main Sheet'!A4,Sheet1!B:B,0)),"") -> 45162
A14: B L No.
A15: =IFERROR(INDEX(Sheet1!I:I,MATCH('Main Sheet'!A4,Sheet1!B:B,0)),"") -> 100380025849
A17: Invoice Amount
A18: =IFERROR(INDEX(Sheet2!C:C,MATCH('Main Sheet'!A4,Sheet2!A:A,0)),"") -> 10607.6

Sheet Sheet2
A1: Invoice No. | B1: Invoice Date | C1: Invoice Amount | D1: Adavance | E1: AR Date | F1: Final | G1: FR Date | H1: Remaning Amount | I1: RA Date | J1: Party Name | K1: Company Name | L1: Product | M1: Adjustment Amount
A2: BK031 | B2: 45376 | C2: 5152.44 | J2: Chinh Nguyen | K2: MIK INVESTMENT TRADING JOINT STOCK COMPANY | L2: Absolute Black Mix
A3: BK030 | B3: 45373 | C3: 6580.6 | J3: Mr Tuan | K3: Cong Ty Tnhh | L3: Tan Brown
A4: BK029 | B4: 45367 | C4: 4929.12 | J4: Chinh Nguyen | K4: MIK INVESTMENT TRADING JOINT STOCK COMPANY | L4: Absolute Black Short
A5: BK028 | B5: 45364 | C5: 9031.2 | J5: VK | K5: A-A STONE INVESTMENT | L5: Absolute Black
A6: BK027 | B6: 45362 | C6: 13123.89 | D6: 1000 | E6: 45358 | J6: Mr Tuan | K6: Cong Ty Tnhh | L6: Alaska Gold
A7: BK026 | B7: 45343 | C7: 5276.39 | J7: Tong Viet | K7: Winstone | L7: Gold/fish/forest
A8: BK025 | B8: 45330 | C8: 5014.08 | F8: 3205 | G8: 45000 | J8: le Huan | K8: MK Trading | L8: Absolute Black Mix
A9: BK024 | B9: 45328 | C9: 8819.01 | D9: 980 | E9: 45330 | F9: 7789 | G9: 44990 | J9: Mr Tuan | K9: Cong Ty Tnhh | L9: Hassan Mix | M9: =C9-(D9+F9+H9) -> 50.01
A10: BK023 | B10: 44957 | C10: 4842 | F10: 4842 | G10: 45365 | J10: Le Hue | K10: MK Trading | L10: Alaska Gold | M10: =C10-(D10+F10+H10) -> #VALUE!
A11: BK022 | B11: 45286 | C11: 5484 | F11: 5459 | G11: 44943 | J11: Hoang Duy | K11: MK Trading | L11: Hassan Long | M11: =C11-(D11+F11+H11) -> #VALUE!
A12: BK021 | B12: 45264 | C12: 5219.54 | F12: 10355 | G12: 45289 | J12: Hoang Duy | K12: MK Trading | L12: Hassan | M12: =(C12+C13)-F12 -> 58.52
A13: BK020 | B13: 45264 | C13: 5193.98 | L13: Absolute Black | N13: 5541
A14: BK019 | B14: 45237 | C14: 5494.12 | F14: 3416 | G14: 45259 | H14: 1725 | I14: 45323 | J14: Le Huan | K14: MK Trading | L14: Hassan Green | M14: =C14-(D14+F14+H14) -> #VALUE!
A15: BK018 | B15: 45225 | C15: 4981.29 | F15: 4956 | G15: 45250 | J15: Vo Hau | K15: MK Trading | L15: Galaxy Short | M15: =C15-(D15+F15+H15) -> #VALUE!
A16: BK017 | B16: 45221 | C16: 5130 | F16: =F19 -> 9816 | G16: =G19 -> 45245 | J16: TDP | K16: Quynh Kien | L16: Black Short | M16: =C16-(D16+F16+H16) -> #VALUE!
A17: BK016 | B17: 45221 | C17: 5487.73 | F17: 11022 | G17: 45245 | J17: Hoang Duy | K17: MK Trading | L17: Hassan | M17: =(C17+C18)-F17 -> 25.63
A18: BK015 | B18: 45218 | C18: 5559.9
A19: BK014 | B19: 45216 | C19: 5682.67 | F19: 9816 | G19: 45245 | J19: TDP | K19: Quynh Kien | L19: Absolute Black | M19: =(C19+C20)-F19 -> 1327.42
A20: BK013 | B20: 45204 | C20: 5460.75
A21: BK012 | B21: 45180 | C21: 5312.4 | F21: 4186 | G21: 45226 | J21: TDP | K21: Quynh Kien | L21: Absolute Black | M21: =C21-(D21+F21+H21) -> #VALUE!
A22: BK011 | B22: 45177 | C22: 10831.92 | D22: 972.5 | E22: 45170 | F22: 8750 | G22: 45222 | J22: Mr Tuan | K22: Tran Gia | L22: Ruby Red | M22: =C22-(D22+F22+H22) -> #VALUE!
A23: BK010 | B23: 45176 | C23: 11243 | D23: 0 | E23: - | F23: 10207 | G23: 45205 | J23: Hoang Duy | K23: MK Trading | L23: Alaska Gold | M23: =C23-(D23+F23+H23) -> #VALUE!
A24: BK08 | B24: 45161 | C24: 10607.6 | D24: 0 | E24: - | F24: 9911 | G24: 45195 | H24: 625 | I24: 45287 | J24: Kien Coung | K24: DG Stone | L24: Alaska Gold | M24: =C24-(D24+F24+H24) -> 71.6
A25: BK07 | B25: 45159 | C25: 9071.11 | D25: 0 | E25: - | F25: 14891 | G25: 45187 | H25: 3564 | I25: 45595 | J25: Le Huan | K25: Thoi dai Stone | L25: Absolute Mix | M25: =(C26+C25)-(F25+H25) -> -127.81
A26: BK06 | B26: 45159 | C26: 9256.08 | D26: 0 | E26: - | G26: 45187 | J26: Le Huan | K26: Thoi dai Stone | L26: Absolute Mix
A27: BK05 | B27: 45156 | C27: 6485.28 | D27: 960 | E27: 45154 | F27: 6426 | G27: 45177 | J27: Hoang Duy | K27: MK Trading | L27: Absolute Mix | M27: =C27-(D27+F27+H27) -> #VALUE! | O27: 13
A28: BK04 | B28: 45043 | C28: 7290.17 | D28: 967.5 | E28: 45036 | F28: 0 | G28: - | J28: Thanh | K28: Trang Long | L28: Tan Brown | M28: =C28-(D28+F28+H28) -> #VALUE! | O28: 14
A29: BK03 | B29: 45040 | C29: 7178.08 | D29: 967.5 | E29: 45036 | F29: 0 | G29: - | J29: Thanh | K29: Trang Long | L29: Tan Brown | M29: =C29-(D29+F29+H29) -> #VALUE! | O29: 17
A30: BK02 | B30: 45030 | C30: 6746 | D30: 975 | E30: 45021 | F30: 5721 | G30: 45064 | J30: Tong Viet | K30: VU MINH DEVELOPMENT | L30: Ash Black | M30: =C30-(D30+F30+H30) -> #VALUE! | O30: 3
A31: BK01 | B31: 45043 | C31: 11218.71 | D31: 984 | E31: 45019 | F31: 10193.71 | G31: 45071 | J31: Da Op Lat | K31: DG Stone | L31: Alaska Gold | M31: =C31-(D31+F31+H31) -> #VALUE! | O31: 4
A32: BK004 | B32: 44994 | C32: 5811.6 | D32: 0 | E32: - | F32: 5432 | G32: 45027 | J32: Nguyen | K32: MK Trading | L32: Tan Brown | M32: =C32-(D32+F32+H32) -> #VALUE!
A33: BK003 | B33: 44984 | C33: 8534.76 | D33: 984 | E33: 44984 | F33: 7509 | G33: 45006 | J33: Da Op Lat | K33: DG Stone | L33: Galaxy | M33: =C33-(D33+F33+H33) -> #VALUE!
A34: BK002 | B34: 44977 | C34: 27473.33 | D34: 2975 | E34: 44959 | F34: 24148 | G34: 45001 | J34: La Le Huy | K34: MK Trading | M34: =C34-(D34+F34+H34) -> #VALUE!
A35: BK001 | B35: 31 November 2022 | C35: 8565.37 | D35: 984 | E35: 45259 | F35: 7540 | G35: 44924 | J35: Tong Viet | K35: NamHuy Import Export | M35: =C35-(D35+F35+H35) -> #VALUE!

Sheet Sheet1
A1: Invoice Date | B1: Invoice No. | C1: Shipping Bill No. | D1: Shipping Bill Date | E1: CHA | F1: DBK Amount | G1: DBK Date | H1: Bank BRC | I1: BL No. | J1: RodTap Amount | K1: RoDTEP | L1: E-Script
A2: =IFERROR(INDEX(Sheet2!B:B,MATCH(Sheet1!B2,Sheet2!A:A,0)),"") -> 31 November 2022 | B2: BK001 | C2: 5861001 | D2: 01-DEC-22 | E2: Bilss Global | F2: 6719 | G2: 44917 | H2: Done | I2: COAU7242516950 | J2: 6719 | K2: Received
A3: =IFERROR(INDEX(Sheet2!B:B,MATCH(Sheet1!B3,Sheet2!A:A,0)),"") -> 44977 | B3: BK002 | C3: 7919940 | D3: 44977 | E3: Bilss Global | F3: 22009 | G3: 45005 | H3: Done | I3: COAU7243285242 | J3: 22010 | K3: Received
A4: =IFERROR(INDEX(Sheet2!B:B,MATCH(Sheet1!B4,Sheet2!A:A,0)),"") -> 44984 | B4: BK003 | C4: 8128514 | D4: 44985 | E4: Bilss Global | F4: 6843 | G4: 44991 | H4: Done | I4: COAU7243414046 | J4: 6842 | K4: Received
A5: =IFERROR(INDEX(Sheet2!B:B,MATCH(Sheet1!B5,Sheet2!A:A,0)),"") -> 44994 | B5: BK004 | C5: 8374152 | D5: 44995 | E5: Bilss Global | F5: 4604 | G5: 45005 | H5: Done | I5: ONEYMAAD05343400 | K5: Received
A6: =IFERROR(INDEX(Sheet2!B:B,MATCH(Sheet1!B6,Sheet2!A:A,0)),"") -> 45043 | B6: BK01 | C6: 9157562 | D6: 45024 | E6: Bilss Global | F6: 9898 | G6: 45051 | H6: Done | I6: SSLMDHPHCAA0066 | J6: 9098 | K6: Received
A7: =IFERROR(INDEX(Sheet2!B:B,MATCH(Sheet1!B7,Sheet2!A:A,0)),"") -> 45030 | B7: BK02 | C7: 9350534 | D7: 45033 | E7: Bilss Global | F7: 5297 | G7: 45056 | H7: Done | I7: SSLMDHPHCAA0067 | J7: 5297 | K7: Received
A8: =IFERROR(INDEX(Sheet2!B:B,MATCH(Sheet1!B8,Sheet2!A:A,0)),"") -> 45040 | B8: BK03 | C8: 9564580 | D8: 45042 | E8: Bilss Global | F8: 5696 | G8: 45056 | I8: COAU7243995790 | J8: 5696 | K8: Received
A9: =IFERROR(INDEX(Sheet2!B:B,MATCH(Sheet1!B9,Sheet2!A:A,0)),"") -> 45043 | B9: BK04 | C9: 9620734 | D9: 45044 | E9: Bilss Global | F9: 5788 | G9: 45056 | I9: COAU7243995790 | J9: 5788 | K9: Received
A10: =IFERROR(INDEX(Sheet2!B:B,MATCH(Sheet1!B10,Sheet2!A:A,0)),"") -> 45156 | B10: BK05 | C10: 3307977 | D10: 45157 | E10: RJSL | F10: 5273 | G10: 45462 | H10: Done | I10: 2309003MK | J10: 5274 | K10: Received
A11: =IFERROR(INDEX(Sheet2!B:B,MATCH(Sheet1!B11,Sheet2!A:A,0)),"") -> 45159 | B11: BK06 | C11: 3337713 | D11: 45159 | E11: RJSL | F11: 7551 | G11: 45174 | H11: Done | I11: 2309019MK | J11: 7551 | K11: Received
A12: =IFERROR(INDEX(Sheet2!B:B,MATCH(Sheet1!B12,Sheet2!A:A,0)),"") -> 45159 | B12: BK07 | C12: 3403745 | D12: 45161 | E12: RJSL | F12: 7391 | G12: 45462 | H12: Done | I12: 2309019MK289 | J12: 7391 | K12: Received
A13: =IFERROR(INDEX(Sheet2!B:B,MATCH(Sheet1!B13,Sheet2!A:A,0)),"") -> 45161 | B13: BK08 | C13: 3440075 | D13: 45162 | E13: Perfect | F13: 8547 | G13: 45190 | H13: Done | I13: 100380025849 | J13: 8547 | K13: Received
A14: =IFERROR(INDEX(Sheet2!B:B,MATCH(Sheet1!B14,Sheet2!A:A,0)),"") -> 45176 | B14: BK010 | C14: 3799502 | D14: 45177 | E14: Perfect | F14: 9070 | G14: 45233 | H14: Done | I14: 100380028112 | J14: 9070
A15: =IFERROR(INDEX(Sheet2!B:B,MATCH(Sheet1!B15,Sheet2!A:A,0)),"") -> 45177 | B15: BK011 | C15: 3817667 | D15: 45178 | E15: Perfect | F15: 8904 | G15: 45233 | H15: Done | I15: 10300047626 | J15: 8904
A16: =IFERROR(INDEX(Sheet2!B:B,MATCH(Sheet1!B16,Sheet2!A:A,0)),"") -> 45180 | B16: BK012 | C16: 3868042 | D16: 45181 | E16: RJSL | F16: 4309 | G16: 45453 | H16: Done | I16: 2309114QK | J16: 4309 | K16: Received
A17: =IFERROR(INDEX(Sheet2!B:B,MATCH(Sheet1!B17,Sheet2!A:A,0)),"") -> 45204 | B17: BK013 | C17: 4479626 | D17: 45206 | E17: RJSL | F17: 4442 | G17: 45469 | H17: Done | I17: 2310021QK | J17: 4442 | K17: Received
A18: =IFERROR(INDEX(Sheet2!B:B,MATCH(Sheet1!B18,Sheet2!A:A,0)),"") -> 45216 | B18: BK014 | C18: 4758161 | D18: 45218 | E18: RJSL | F18: 4625 | G18: 45468 | H18: Done | I18: 2311012QK | J18: 4625 | K18: Received
A19: =IFERROR(INDEX(Sheet2!B:B,MATCH(Sheet1!B19,Sheet2!A:A,0)),"") -> 45218 | B19: BK015 | C19: 4792598 | D19: 45219 | E19: Glottis | F19: 4551 | G19: 45237 | H19: Done | I19: GPLMAAHPH2302292 | J19: 4551 | K19: Received
A20: =IFERROR(INDEX(Sheet2!B:B,MATCH(Sheet1!B20,Sheet2!A:A,0)),"") -> 45221 | B20: BK016 | C20: 4848440 | D20: 45222 | E20: Glottis | F20: 4496 | G20: 45441 | H20: Done | I20: GPLKATHPH2302299 | J20: 4495 | K20: Received
A21: =IFERROR(INDEX(Sheet2!B:B,MATCH(Sheet1!B21,Sheet2!A:A,0)),"") -> 45221 | B21: BK017 | C21: 4845527 | D21: 45222 | E21: Glottis | F21: 4201 | G21: 45441 | H21: Done | I21: GPLKATHPH2302300 | J21: 4201 | K21: Received
A22: =IFERROR(INDEX(Sheet2!B:B,MATCH(Sheet1!B22,Sheet2!A:A,0)),"") -> 45225 | B22: BK018 | C22: 4929602 | D22: 45226 | E22: RJSL | F22: 4049 | G22: 45469 | H22: Done | I22: 2311022MK | J22: 4049 | K22: Received
A23: =IFERROR(INDEX(Sheet2!B:B,MATCH(Sheet1!B23,Sheet2!A:A,0)),"") -> 45237 | B23: BK019 | C23: 5227518 | D23: 45238 | E23: RJSL | F23: 4461 | G23: 45469 | H23: Done | I23: 2311156MK | J23: 4461 | K23: Received
A24: =IFERROR(INDEX(Sheet2!B:B,MATCH(Sheet1!B24,Sheet2!A:A,0)),"") -> 45264 | B24: BK020 | C24: 5874109 | D24: 45267 | E24: Glottis | F24: 4244 | H24: Done | I24: GPLMAAHPH2302761 | J24: 4244 | K24: Received
A25: =IFERROR(INDEX(Sheet2!B:B,MATCH(Sheet1!B25,Sheet2!A:A,0)),"") -> 45264 | B25: BK021 | C25: 5951661 | D25: 45271 | E25: Glottis | F25: 4265 | H25: Done | I25: GPLMAAHPH2302808 | J25: 4265 | K25: Received
A26: =IFERROR(INDEX(Sheet2!B:B,MATCH(Sheet1!B26,Sheet2!A:A,0)),"") -> 45286 | B26: BK022 | C26: 6301293 | D26: 45286 | E26: Glottis | F26: 4502 | G26: 45300 | H26: Done | I26: GPLMAAHPH2302987 | J26: 4502 | K26: Received
A27: =IFERROR(INDEX(Sheet2!B:B,MATCH(Sheet1!B27,Sheet2!A:A,0)),"") -> 44957 | B27: BK023 | C27: 7217927 | D27: 45324 | E27: Perfect | F27: 3808 | G27: 44987 | H27: Done | I27: A37E000020 | J27: 3808
A28: =IFERROR(INDEX(Sheet2!B:B,MATCH(Sheet1!B28,Sheet2!A:A,0)),"") -> 45328 | B28: BK024 | C28: 7373152 | D28: 45330 | E28: RJSL | F28: 7233 | H28: Done | I28: 2402092 | J28: 7232 | K28: Received
A29: =IFERROR(INDEX(Sheet2!B:B,MATCH(Sheet1!B29,Sheet2!A:A,0)),"") -> 45330 | B29: BK025 | C29: 7393730 | D29: 45331 | E29: Glottis | F29: 4093 | G29: 45483 | H29: Done | I29: GPLMAAHPH2303577 | J29: 4093 | K29: Received
A30: =IFERROR(INDEX(Sheet2!B:B,MATCH(Sheet1!B30,Sheet2!A:A,0)),"") -> 45343 | B30: BK026 | C30: 7788001 | D30: 45345 | E30: True Line | F30: 4239 | G30: 44999 | H30: Done | I30: SSLMDHPHCAA0096 | J30: 4239 | K30: Received
A31: =IFERROR(INDEX(Sheet2!B:B,MATCH(Sheet1!B31,Sheet2!A:A,0)),"") -> 45362 | B31: BK027 | C31: 8275813 | D31: 45364 | E31: True Line | F31: 10663 | G31: 45388 | H31: Done | I31: LEOJAIHPH23OO63 | J31: 19194 | K31: Received
A32: =IFERROR(INDEX(Sheet2!B:B,MATCH(Sheet1!B32,Sheet2!A:A,0)),"") -> 45364 | B32: BK028 | C32: 8316663 | D32: 45365 | E32: Glottis | F32: 7352 | G32: 45385 | H32: Done | I32: GPLMAADAD2304014 | J32: 13234 | K32: Received
A33: =IFERROR(INDEX(Sheet2!B:B,MATCH(Sheet1!B33,Sheet2!A:A,0)),"") -> 45367 | B33: BK029 | C33: 8408984 | D33: 45369 | E33: Glottis | F33: 4009 | G33: 45386 | H33: Done | I33: GPLMAAHPH2304102 | J33: 7216 | K33: Received
A34: =IFERROR(INDEX(Sheet2!B:B,MATCH(Sheet1!B34,Sheet2!A:A,0)),"") -> 45373 | B34: BK030 | C34: 8574361 | D34: 45374 | E34: Glottis | F34: 5359 | G34: 45398 | H34: Done | I34: GPLMAAHPH2304209 | J34: 9647 | K34: Received
A35: =IFERROR(INDEX(Sheet2!B:B,MATCH(Sheet1!B35,Sheet2!A:A,0)),"") -> 45376 | B35: BK031 | C35: 8620872 | D35: 45377 | E35: Glottis | F35: 4188 | G35: 45398 | H35: Done | I35: GPLMAAHPH2400043 | J35: 7538 | K35: Received
A36: =IFERROR(INDEX(Sheet2!B:B,MATCH(Sheet1!#REF!,Sheet2!A:A,0)),"")
A37: =IFERROR(INDEX(Sheet2!B40:B71,MATCH(Sheet1!#REF!,Sheet2!A39:A71,0)),"")
A38: =IFERROR(INDEX(Sheet2!B41:B72,MATCH(Sheet1!#REF!,Sheet2!A40:A72,0)),"")
A39: =IFERROR(INDEX(Sheet2!B43:B73,MATCH(Sheet1!#REF!,Sheet2!A41:A73,0)),"")
A40: =IFERROR(INDEX(Sheet2!B43:B74,MATCH(Sheet1!#REF!,Sheet2!A43:A74,0)),"")
...

Sheet Sheet3
A1: 8620872 | B1: 26.03.2024 | C1: 122142 | D1: 15.04.2024 | F1: INMAA1 | G1: 7538
B2: 8408984 | C2: 18.03.2024 | D2: 121480 | E2: 05.04.2024 | G2: INMAA1 | H2: 7216
B3: 8275813 | C3: 13.03.2024 | D3: 121162 | E3: 02.04.2024 | G3: INMUN1 | H3: 19194
B4: 6301293 | C4: 26.12.2023 | D4: 115537 | E4: 08.01.2024 | G4: INMAA1 | H4: 4502
B5: 4792598 | C5: 20.10.2023 | D5: 110468 | E5: 03.11.2023 | G5: INMAA1 | H5: 4551
B6: 3337713 | C6: 21.08.2023 | D6: 105778 | E6: 04.09.2023 | G6: INMAA1 | H6: 7551
B7: 9564580 | C7: 26.04.2023 | D7: 94447/2023 | E7: 08.05.2023 | G7: INMAA1 | H7: 5696
B8: 9620734 | C8: 28.04.2023 | D8: 94447/2023 | E8: 08.05.2023 | G8: INMAA1 | H8: 5788
B9: 8374152 | C9: 10.03.2023 | D9: 93564/2023 | E9: 28.04.2023 | G9: INMAA1 | H9: 4604
B10: 8128514 | C10: 28.02.2023 | D10: 90500/2023 | E10: 20.03.2023 | G10: INMAA1 | H10: 6842

Sheet Documentation
A1: Documents | B1: BK031 | C1: BK030 | D1: BK029 | E1: BK028 | F1: BK027 | G1: BK026 | H1: BK025 | I1: BK024 | J1: BK023 | K1: BK022
A2: Proforma Invoice
A3: Measurment Sheet
A4: Purchase oder
A5: Commercial invoice
A6: Packing List
A7: Shipping Bill
A8: Bill Leading
A9: AIFTA
A10: Insurannce
A11: Logistic Invoice
A12: Purchase Invoice
A13: Bank Receipt
... A15: E-Script

Sheet BK23
A1: BK023
A2: Alaska gold | B2: 472.46 | C2: 23.25 | D2: =B2*C2 -> 10984.695
A3: Invoice Value | B3: 472.46 | C3: 10.25 | D3: =B3*C3 -> 4842.715
D4: =D2-D3 -> 6141.98
B5: Advance | C5: VIT Account | D5: 1000
D6: =D4-D5 -> 5141.98
A9: BK025
A10: Absolute Black Long | B10: 214.56 | C10: 23 | D10: =B10*C10 -> 4934.88
A11: Absolute Black Short | B11: 221.76 | C11: 18 | D11: =B11*C11 -> 3991.68
D12: =SUM(D10:D11) -> 8926.56
B13: Invoice Value
B14: 214.56 | C14: 12 | D14: =B14*C14 -> 2574.72
B15: 221.76 | C15: 11 | D15: =B15*C15 -> 2439.36
C16: Indian Account | D16: =SUM(D14:D15) -> 5014.08 | E16: 1784 | F16: =D16-E16 -> 3230.08
C17: VIT Account Due | D17: =D12-D16 -> 3912.48
A20: BK026
A21: Forest Black | B21: 191.11 | C21: 10.75 | D21: =B21*C21 -> 2054.4325
A22: Fish Black | B22: 178.79 | C22: 11.25 | D22: =B22*C22 -> 2011.3875
A23: Alaska Gold | B23: 158.4 | C23: 25.5 | D23: =B23*C23 -> 4039.2
D24: =SUM(D21:D23) -> 8105.02
B25: Invoice Value
A26: Forest Black | B26: 191.11 | C26: 8 | D26: =B26*C26 -> 1528.88
A27: Fish Black | B27: 178.79 | C27: 9 | D27: =B27*C27 -> 1609.11
A28: Alaska Gold | B28: 158.4 | C28: 13.5 | D28: =B28*C28 -> 2138.4
B29: Indian Account Due | D29: =SUM(D26:D28) -> 5276.39
B30: VIT Account Due | D30: =D24-D29 -> 2828.63
B31: Adavnce | C31: VIT Account | D31: 1000
B32: VIT Account Due | D32: =D30-D31 -> 1828.63
A36: BK029
A37: Absolute Black | B37: 410.76 | C37: 18.6 | D37: =B37*C37 -> 7640.136
A38: invoice Value | B38: 410.76 | C38: 12 | D38: =B38*C38 -> 4929.12
C39: In VND -Account | D39: =D37-D38 -> 2711.016
C40: in IND -Account | D40: =D38 -> 4929.12
A43: BK031
A44: Actual Price
A45: Absolute Black Short | B45: 199.25 | C45: 23.5 | D45: =B45*C45 -> 4682.375
A46: Absolute Black Long | B46: 251.04 | C46: 18.6 | D46: =B46*C46 -> 4669.344
A47: Total Amount | D47: =SUM(D45:D46) -> 9351.719
A48: Invoice Amount
A49: Absolute Black Long | B49: 199.25 | C49: 12 | D49: =B49*C49 -> 2391
...
